Workbook

Sheet Introduction, key and version
C1: Supporting spreadsheet to the economic appraisal for an FCERM project
C3: Introduction | F3: This spreadsheet provides example tables and methods for undertaking principle calculations required for your FCERM economic appraisal.
F5: No attempt has been made to show a complete set of data flowing through the tabs.
F7: You should enter your own project data to enable the automatic calculation you need in your economic appraisal.
F9: Each tab and its function is described here with examples of when to use it.
C11: Summary | F11: This is an example summary table. It shows the breakdown of present value damages for a range of categories of damage. It converts damages to benefits and combines with costs to generate a benefit cost ratio and Net Present Value suitable for use when identifying the preferred option. See FCERM Appraisal Guidance section 9 (costs), section 10 (damages and benefits), section 11 (preferred option).
F13: You can insert more columns if you need to add more options. You can insert more rows if you need to add more categories of damage.
F15: All options in this table must be compared over the same appraisal period, normally 100 years. See FCERM Appraisal Guidance section 5.6.
C17: Annual Average Damage | F17: This tab converts the damages from a range of different severity of event into an Average Annual Damage. See the FCERM Apprasial Guidance section 10.
F19: This is presented in a summary form with one line for each category of damage.
F21: This concept will need to be replicated to produce an average annual damage for each property if you need to test the effects of capping.
F23: The annual average damage is calculated by measuring the area unde the curve of damage against annual probability. The table automatically calculates this area.
F25: Categories of damage are presented in two sections - those with the standard discount rate, and those with the health discount rate.
F27: If it is not proportionate for the appraisal to include climate change, the Present Value damages can be taken from here to the summary table.
F29: If climate change is included, then annual average damages will need to be calculated for each epoch, for each option. These can then be converted into a stream of annual damages and discounted to a present value using the PV damages tab.
C31: Breach Damage Do -nothing | F31: This tab should be used to determine damages when there is a step change in the FCERM circumstanc for example, where a defence is likely to fail and once failed then the rate of damages is greatly increased. The table also allows for one off losses to occur in the year of the breach.
F33: Sensitivity testing on the residual life and current probability of failure can be easily done by changing these parameters.
C35: Erosion | F35: This tab provides a methodology for calculating erosion losses over time. Each asset can only be lost once. The probability of its loss can be spread across a number of time periods.
F37: Your options should be based on the duration of time for which erosion can be delayed.
F39: This table will work with losses predicted within 200 years.
C41: Present Value (PV) costs | F41: This tab allows the user to enter the costs associated with each of their FCERM options over the appraisal period. The tables automatically calculates the Present Value Cost. See the FCERM Appraisal Guidance section 9.
F43: Note: future costs should not include inflation when calcualting PV Costs for the economic case.
C45: Present Value (PV) benefits | F45: This tab works the same way as the PV costs tab, but it contains both the standard and the health discount rate.
F47: This converts a stream of annual losses which may change over time into a Present Value using discounting.
C51: Key
C53: Key to cells in tabs
F54: Cells needing input
F56: Cells that automatically calculate
F58: Key assumptions that are fixed (such as the discount rates, or the start and end years for a 100 year appraisal period)
F60: Background and information (for example, headings)
C64: Version Control
C66: Version | F66: Change notes
C67: 1 | F67: Released April 2022 - spreadsheet to support new FCERM Appraisal Guidance released in March 2022.

Sheet Summary
B1: Project Summary Sheet
A2: Client/Authority | E2: Prepared (date) | F2: 44562
E3: Printed | F3: =TODAY() -> 44692
A4: Project name | E4: Prepared by
E5: Checked by
A6: Project reference | E6: Checked date
A7: Base date for estimates (year 0) | B7: mmm-yyyy | C7: 44562
A8: Scaling factor (e.g. £m, £k, £) | C8: £k | D8: (used for all costs, losses and benefits)
A9: Optimism bias adjustment factor | C9: 0.6
A10: Costs and benefits of options
D11: =CONCATENATE("Costs and benefits ",$C$8) -> Costs and benefits £k
A12: Option name | B12: =A47 -> Do Nothing | C12: =A48 -> Do Minimum | D12: =A49 -> Option 3 | E12: =A50 -> Option 4 | F12: =A51 -> Option 5
A13: AEP or SoP (where relevant) when built | B13: 0.05 | C13: 0.05 | D13: 0.005 | E13: 0.005 | F13: 0.0002
A14: AEP or SoP at end of apprisal period | B14: 0.2 | C14: 0.1 | D14: 0.01 | E14: 0.01 | F14: 0.005
A15: COSTS:
A16: PV capital costs | B16: ='PV Costs'!H12 -> 0 | C16: ='PV Costs'!Q12 -> 0 | D16: ='PV Costs'!Z12 -> 0 | E16: ='PV Costs'!AI12 -> 0 | F16: ='PV Costs'!AR12 -> 0
A17: PV operation and maintenance costs | B17: ='PV Costs'!I12 -> 0 | C17: ='PV Costs'!R12 -> 0 | D17: ='PV Costs'!AA12 -> 0 | E17: ='PV Costs'!AJ12 -> 0 | F17: ='PV Costs'!AS12 -> 0
A18: PV other | B18: ='PV Costs'!J12 -> 0 | C18: ='PV Costs'!S12 -> 0 | D18: ='PV Costs'!AB12 -> 0 | E18: ='PV Costs'!AK12 -> 0 | F18: ='PV Costs'!AT12 -> 0
A19: Optimism bias adjustment | B19: =(B16+B17+B18)*($C$9) -> 0 | C19: =(C16+C17+C18)*($C$9) -> 0 | D19: =(D16+D17+D18)*($C$9) -> 0 | E19: =(E16+E17+E18)*($C$9) -> 0 | F19: =(F16+F17+F18)*($C$9) -> 0
A20: PV negative costs (e.g. sales) | B20: ='PV Costs'!K12 -> 0 | C20: ='PV Costs'!T12 -> 0 | D20: ='PV Costs'!AC12 -> 0 | E20: ='PV Costs'!AL12 -> 0 | F20: ='PV Costs'!AU12 -> 0
A21: =CONCATENATE("Total PV Costs ",C8) -> Total PV Costs £k | B21: =B16+B17+B18+B19-B20 -> 0 | C21: =C16+C17+C18+C19-C20 -> 0 | D21: =D16+D17+D18+D19-D20 -> 0 | E21: =E16+E17+E18+E19-E20 -> 0 | F21: =F16+F17+F18+F19-F20 -> 0
A22: BENEFITS:
A23: PV damages Residential property | B23: ='Annual Average Damage'!L17 -> 0
A24: PV damages Non-Residential property | B24: ='Annual Average Damage'!L18 -> 0
A25: PV damages Mental Health | B25: ='Annual Average Damage'!L24 -> 0
A26: PV damages Risk to Life | B26: ='Annual Average Damage'!L25 -> 0
A27: PV damages Temporary Accommodation | B27: ='Annual Average Damage'!L19 -> 0
A28: PV damages Emergency Services | B28: ='Annual Average Damage'!L26 -> 0
A29: PV damages Environment
A30: PV damages Cars
A31: PV damages other
A32: PV damages Other
A34: =CONCATENATE("Total PV damages ",C8) -> Total PV damages £k | B34: =SUM(B23:B33) -> 0 | C34: =SUM(C23:C33) -> 0 | D34: =SUM(D23:D33) -> 0 | E34: =SUM(E23:E33) -> 0 | F34: =SUM(F23:F33) -> 0
A35: PV Human Intangible stress and health benefits
A36: PV benefits where measured directly as a benefit
A37: =CONCATENATE("Total PV benefits including damages avoided ",C8) -> Total PV benefits including damages avoided £k | C37: =($B$34-C34)+C35+C36 -> 0 | D37: =($B$34-D34)+D35+D36 -> 0 | E37: =($B$34-E34)+E35+E36 -> 0 | F37: =($B$34-F34)+F35+F36 -> 0
A38: DECISION-MAKING CRITERIA:
A40: Net Present Value NPV | C40: =C37-C21 -> 0 | D40: =D37-D21 -> 0 | E40: =E37-E21 -> 0 | F40: =F37-F21 -> 0
A41: Average benefit/cost ratio BCR | C41: =C37/C21 -> #DIV/0! | D41: =D37/D21 -> #DIV/0! | E41: =E37/E21 -> #DIV/0! | F41: =F37/F21 -> #DIV/0!
A42: Incremental benefit/cost ratio IBCR | D42: =(D37-C37)/(D21-C21) -> #DIV/0! | E42: =(E37-D37)/(E21-D21) -> #DIV/0! | F42: =(F37-E37)/(F21-E21) -> #DIV/0! | G42: Check your ordering of options is in accordance with the FCERM-AG decision rule
...

Sheet Annual Average Damage
E1: Annual Average Damage | J1: Sheet Nr.
A2: Client/Authority
A3: =Summary!A3 -> 0
A4: Project name | F4: Option:
A5: =Summary!A5 -> 0 | F5: =Summary!B12 -> Do Nothing
A6: Project reference | D6: =Summary!C6 -> 0
A7: Base date for estimates (year 0) | D7: =Summary!C7 -> 44562 | F7: First year of damage: | I7: 0 | J7: Prepared (date) | L7: =Summary!F2 -> 44562
A8: Scaling factor (e.g. £m, £k, £) | D8: =Summary!C8 -> £k | F8: Last year of period: | I8: 99 | J8: Printed | L8: =Summary!F3 -> 44692
F9: PV factor standard rate: | I9: =VLOOKUP(I8,Metadata!$A$23:$D$122,4)-VLOOKUP(I7,Metadata!$A$23:$D$122,4)+VLOOKUP(I7,Metadata!$A$23:$D$122,3) -> 29.812545 | J9: Prepared by | L9: =Summary!F4 -> 0
F10: PV factor health rate: | I10: =VLOOKUP(I8,Metadata!$A$23:$H$122,8)-VLOOKUP(I7,Metadata!$A$23:$H$122,8)+VLOOKUP(I7,Metadata!$A$23:$H$122,7) -> 54.354029 | J10: Checked by | L10: =Summary!F5 -> 0
A11: Applicable year (if time varying) | D11: 0 | J11: Checked date | L11: =Summary!F6 -> 0
C12: Average waiting time (yrs) between events/frequency per year | L12: Total PV
C13: 2 | D13: 5 | E13: 10 | F13: 20 | G13: 50 | H13: 75 | I13: 100 | J13: 200 | K13: Infinity | L13: =D8 -> £k
C14: =1/C13 -> 0.5 | D14: =1/D13 -> 0.2 | E14: =1/E13 -> 0.1 | F14: =1/F13 -> 0.05 | G14: =1/G13 -> 0.02 | H14: =1/H13 -> 0.013333333 | I14: =1/I13 -> 0.01 | J14: =1/J13 -> 0.005 | K14: 0
A15: Damage category | C15: =CONCATENATE("Damage ",D8) -> Damage £k
A16: Standard Discount Rate
A17: Residential property | C17: 0 | K17: =J17+(J17-I17)*(J$14-K$14)/(I$14-J$14) -> 0 | L17: =(($C$14-$D$14)*(C17+D17)++($D$14-$E$14)*(D17+E17)+($E$14-$F$14)*(E17+F17)+($F$14-$G$14)*(F17+G17)+($G$14-$H$14)*(G17+H17)+($H$14-$I$14)*(H17+I17)+($I$14-$J$14)*(I17+J17)+($J$14-$K$14)*(J17+K17)+$K$14*K17)*$I$9/2 -> 0
A18: Non-Residential property | C18: 0 | K18: =J18+(J18-I18)*(J$14-K$14)/(I$14-J$14) -> 0 | L18: =(($C$14-$D$14)*(C18+D18)+($D$14-$E$14)*(D18+E18)+($E$14-$F$14)*(E18+F18)+($F$14-$G$14)*(F18+G18)+($G$14-$H$14)*(G18+H18)+($H$14-$I$14)*(H18+I18)+($I$14-$J$14)*(I18+J18)+($J$14-$K$14)*(J18+K18)+$K$14*K18)*$I$9/2 -> 0
A19: Temporary Accommodation | C19: 0 | K19: =J19+(J19-I19)*(J$14-K$14)/(I$14-J$14) -> 0 | L19: =(($C$14-$D$14)*(C19+D19)+($D$14-$E$14)*(D19+E19)+($E$14-$F$14)*(E19+F19)+($F$14-$G$14)*(F19+G19)+($G$14-$H$14)*(G19+H19)+($H$14-$I$14)*(H19+I19)+($I$14-$J$14)*(I19+J19)+($J$14-$K$14)*(J19+K19)+$K$14*K19)*$I$9/2 -> 0
A20: Cars | C20: 0 | K20: =J20+(J20-I20)*(J$14-K$14)/(I$14-J$14) -> 0 | L20: =(($C$14-$D$14)*(C20+D20)+($D$14-$E$14)*(D20+E20)+($E$14-$F$14)*(E20+F20)+($F$14-$G$14)*(F20+G20)+($G$14-$H$14)*(G20+H20)+($H$14-$I$14)*(H20+I20)+($I$14-$J$14)*(I20+J20)+($J$14-$K$14)*(J20+K20)+$K$14*K20)*$I$9/2 -> 0
A21: Other (Insert name) | C21: 0 | K21: =J21+(J21-I21)*(J$14-K$14)/(I$14-J$14) -> 0 | L21: =(($C$14-$D$14)*(C21+D21)+($D$14-$E$14)*(D21+E21)+($E$14-$F$14)*(E21+F21)+($F$14-$G$14)*(F21+G21)+($G$14-$H$14)*(G21+H21)+($H$14-$I$14)*(H21+I21)+($I$14-$J$14)*(I21+J21)+($J$14-$K$14)*(J21+K21)+$K$14*K21)*$I$9/2 -> 0
A22: Other (Insert name) | C22: 0 | K22: =J22+(J22-I22)*(J$14-K$14)/(I$14-J$14) -> 0 | L22: =(($C$14-$D$14)*(C22+D22)+($D$14-$E$14)*(D22+E22)+($E$14-$F$14)*(E22+F22)+($F$14-$G$14)*(F22+G22)+($G$14-$H$14)*(G22+H22)+($H$14-$I$14)*(H22+I22)+($I$14-$J$14)*(I22+J22)+($J$14-$K$14)*(J22+K22)+$K$14*K22)*$I$9/2 -> 0
A23: Health Discount Rate
A24: Mental Health | C24: 0 | K24: =J24+(J24-I24)*(J$14-K$14)/(I$14-J$14) -> 0 | L24: =(($C$14-$D$14)*(C24+D24)+($D$14-$E$14)*(D24+E24)+($E$14-$F$14)*(E24+F24)+($F$14-$G$14)*(F24+G24)+($G$14-$H$14)*(G24+H24)+($H$14-$I$14)*(H24+I24)+($I$14-$J$14)*(I24+J24)+($J$14-$K$14)*(J24+K24)+$K$14*K24)*$I$10/2 -> 0
A25: Risk to Life | C25: 0 | K25: =J25+(J25-I25)*(J$14-K$14)/(I$14-J$14) -> 0 | L25: =(($C$14-$D$14)*(C25+D25)+($D$14-$E$14)*(D25+E25)+($E$14-$F$14)*(E25+F25)+($F$14-$G$14)*(F25+G25)+($G$14-$H$14)*(G25+H25)+($H$14-$I$14)*(H25+I25)+($I$14-$J$14)*(I25+J25)+($J$14-$K$14)*(J25+K25)+$K$14*K25)*$I$10/2 -> 0
A26: Emergency services | C26: =(C17+C18)*0.107 -> 0 | K26: =(K17+K18)*0.107 -> 0 | L26: =(($C$14-$D$14)*(C26+D26)+($D$14-$E$14)*(D26+E26)+($E$14-$F$14)*(E26+F26)+($F$14-$G$14)*(F26+G26)+($G$14-$H$14)*(G26+H26)+($H$14-$I$14)*(H26+I26)+($I$14-$J$14)*(I26+J26)+($J$14-$K$14)*(J26+K26)+$K$14*K26)*$I$10/2 -> 0
A27: Other (Insert name) | C27: 0 | K27: =J27+(J27-I27)*(J$14-K$14)/(I$14-J$14) -> 0 | L27: =(($C$14-$D$14)*(C27+D27)+($D$14-$E$14)*(D27+E27)+($E$14-$F$14)*(E27+F27)+($F$14-$G$14)*(F27+G27)+($G$14-$H$14)*(G27+H27)+($H$14-$I$14)*(H27+I27)+($I$14-$J$14)*(I27+J27)+($J$14-$K$14)*(J27+K27)+$K$14*K27)*$I$10/2 -> 0
A28: Other (Insert name) | C28: 0 | K28: =J28+(J28-I28)*(J$14-K$14)/(I$14-J$14) -> 0 | L28: =(($C$14-$D$14)*(C28+D28)+($D$14-$E$14)*(D28+E28)+($E$14-$F$14)*(E28+F28)+($F$14-$G$14)*(F28+G28)+($G$14-$H$14)*(G28+H28)+($H$14-$I$14)*(H28+I28)+($I$14-$J$14)*(I28+J28)+($J$14-$K$14)*(J28+K28)+$K$14*K28)*$I$10/2 -> 0
A29: =CONCATENATE("Total Damage per event ",D8) -> Total Damage per event £k | C29: =SUM(C17:C28) -> 0 | D29: =SUM(D17:D28) -> 0 | E29: =SUM(E17:E28) -> 0 | F29: =SUM(F17:F28) -> 0 | G29: =SUM(G17:G28) -> 0 | H29: =SUM(H17:H28) -> 0 | I29: =SUM(I17:I28) -> 0 | J29: =SUM(J17:J28) -> 0 | K29: =SUM(K17:K28) -> 0
A30: Total damage (standard rate) | C30: =SUM(C17:C21) -> 0 | D30: =SUM(D17:D21) -> 0 | E30: =SUM(E17:E21) -> 0 | F30: =SUM(F17:F21) -> 0 | G30: =SUM(G17:G21) -> 0 | H30: =SUM(H17:H21) -> 0 | I30: =SUM(I17:I21) -> 0 | J30: =SUM(J17:J21) -> 0 | K30: =SUM(K17:K21) -> 0
A31: Area (damagexfrequency) | D31: =(C14-D14)*(D30+C30)/2 -> 0 | E31: =(D14-E14)*(E30+D30)/2 -> 0 | F31: =(E14-F14)*(F30+E30)/2 -> 0 | G31: =(F14-G14)*(G30+F30)/2 -> 0 | H31: =(G14-H14)*(H30+G30)/2 -> 0 | I31: =(H14-I14)*(I30+H30)/2 -> 0 | J31: =(I14-J14)*(J30+I30)/2 -> 0 | K31: =(J14-K14)*(K30+J30)/2 -> 0
A32: Total damage (health rate) | C32: =SUM(C24:C28) -> 0 | D32: =SUM(D24:D28) -> 0 | E32: =SUM(E24:E28) -> 0 | F32: =SUM(F24:F28) -> 0 | G32: =SUM(G24:G28) -> 0 | H32: =SUM(H24:H28) -> 0 | I32: =SUM(I24:I28) -> 0 | J32: =SUM(J24:J28) -> 0 | K32: =SUM(K24:K28) -> 0
A33: Area (damagexfrequency) | D33: =(C14-D14)*(D32+C32)/2 -> 0 | E33: =(D14-E14)*(E32+D32)/2 -> 0 | F33: =(E14-F14)*(F32+E32)/2 -> 0 | G33: =(F14-G14)*(G32+F32)/2 -> 0 | H33: =(G14-H14)*(H32+G32)/2 -> 0 | I33: =(H14-I14)*(I32+H32)/2 -> 0 | J33: =(I14-J14)*(J32+I32)/2 -> 0 | K33: =(J14-K14)*(K32+J32)/2 -> 0
G35: Standard | H35: Health
A36: Total area, as above | G36: =SUM(C31:K31) -> 0 | H36: =SUM(C33:K33) -> 0
A37: Present value (assuming no change in damage or event frequency) | G37: =G36*I9 -> 0 | H37: =H36*I10 -> 0 | I37: Total | J37: =SUM(G37:H37) -> 0 | L37: =SUM(L17:L28) -> 0
A38: Notes
A39: Area calculations assume drop to zero at maximum probability.
A40: Default value for the highest possible (infinity) damage assumes continuation of gradient for last two points, an alternative value can
A41: be entered, if appropriate.
...

Sheet Breach Damage Do-nothing
F1: Breach Damage Cost Calculation Sheet - Do Nothing (Linear) | L1: Sheet Nr.
A2: Client/Authority
A3: =Summary!A3 -> 0
A4: Project name | G4: Option:
A5: =Summary!A5 -> 0 | G5: =Summary!A47 -> Do Nothing
A6: Project reference | D6: =Summary!C6 -> 0
A7: Base date for estimates (year 0) | D7: =Summary!C7 -> 44562
A8: Scaling factor (e.g. £m, £k, £) | D8: =Summary!C8 -> £k | L8: Prepared (date) | N8: =Summary!F2 -> 44562
L9: Printed | N9: =Summary!F3 -> 44692
G10: Damage in breach/failure | J10: =$D$8 -> £k | L10: Prepared by | N10: =Summary!F4 -> 0
G11: Ave Annual Damage | I11: Pre-breach | J11: Post Breach | L11: Checked by | N11: =Summary!F5 -> 0
B12: < | E12: > | G12: Epoch 1 2022-2121 | K12: =CONCATENATE($D$8,"/yr") -> £k/yr | L12: Checked date | N12: =Summary!F6 -> 0
A13: Year | B13: 0 | C13: 10 | D13: 30 | E13: 99 | G13: Epoch 2 Set years | K13: =CONCATENATE($D$8,"/yr") -> £k/yr
A14: Breach pb | B14: 0.1 | C14: 1 | D14: 1 | E14: 1 | G14: Epoch 3 Set years | K14: =CONCATENATE($D$8,"/yr") -> £k/yr
G15: Epoch 4 Set years | K15: =CONCATENATE($D$8,"/yr") -> £k/yr
M17: Total PVd | N17: =SUM(N20:N119) -> 0
A18: Year | B18: Standard | C18: Health | D18: Prob of a | F18: Prob that breach/failure: | G18: Damage (cash) due to: | J18: Other damages (cash values) | N18: PV
B19: Discount factor | C19: Discount factor | D19: breach/ failure | E19: occurs in year | F19: has not occurred | G19: breach or failure | H19: Pre - breach damage/yr | I19: Post - breach damage/yr | J19: Damages 1 | K19: Damages 2 | L19: Health Damages | N19: total damage
A20: 0 | B20: =Metadata!C23 -> 1 | C20: =Metadata!G23 -> 1 | D20: =IF(A20<$B$13,$B$14,(IF(A20<$C$13,($B$14+($C$14-$B$14)*(A20-$B$13)/($C$13-$B$13)),(IF(A20<$D$13,($C$14+($D$14-$C$14)*(A20-$C$13)/($D$13-$C$13)),(IF(A20<$E$13,($D$14+($E$14-$D$14)*(A20-$D$13)/($E$13-$D$13)),$E$14))))))) -> 0.1 | E20: =D20 -> 0.1 | F20: =1-E20 -> 0.9 | G20: =E20*$I$10 -> 0 | H20: =$I$12*F20 -> 0 | I20: =$J$12*(1-F20) -> 0 | N20: =(SUM(G20:K20)*B20)+(L20*C20) -> 0
A21: =A20+1 -> 1 | B21: =Metadata!C24 -> 0.96618357 | C21: =Metadata!G24 -> 0.98522167 | D21: =IF(A21<$B$13,$B$14,(IF(A21<$C$13,($B$14+($C$14-$B$14)*(A21-$B$13)/($C$13-$B$13)),(IF(A21<$D$13,($C$14+($D$14-$C$14)*(A21-$C$13)/($D$13-$C$13)),(IF(A21<$E$13,($D$14+($E$14-$D$14)*(A21-$D$13)/($E$13-$D$13)),$E$14))))))) -> 0.19 | E21: =D21*F20 -> 0.171 | F21: =F20-E21 -> 0.729 | G21: =E21*$I$10 -> 0 | H21: =F21*$I$12 -> 0 | I21: =$J$12*(1-F21) -> 0 | N21: =(SUM(G21:K21)*B21)+(L21*C21) -> 0
A22: =A21+1 -> 2 | B22: =Metadata!C25 -> 0.9335107 | C22: =Metadata!G25 -> 0.97066175 | D22: =IF(A22<$B$13,$B$14,(IF(A22<$C$13,($B$14+($C$14-$B$14)*(A22-$B$13)/($C$13-$B$13)),(IF(A22<$D$13,($C$14+($D$14-$C$14)*(A22-$C$13)/($D$13-$C$13)),(IF(A22<$E$13,($D$14+($E$14-$D$14)*(A22-$D$13)/($E$13-$D$13)),$E$14))))))) -> 0.28 | E22: =D22*F21 -> 0.20412 | F22: =F21-E22 -> 0.52488 | G22: =E22*$I$10 -> 0 | H22: =F22*$I$12 -> 0 | I22: =$J$12*(1-F22) -> 0 | N22: =(SUM(G22:K22)*B22)+(L22*C22) -> 0
A23: =A22+1 -> 3 | B23: =Metadata!C26 -> 0.90194271 | C23: =Metadata!G26 -> 0.95631699 | D23: =IF(A23<$B$13,$B$14,(IF(A23<$C$13,($B$14+($C$14-$B$14)*(A23-$B$13)/($C$13-$B$13)),(IF(A23<$D$13,($C$14+($D$14-$C$14)*(A23-$C$13)/($D$13-$C$13)),(IF(A23<$E$13,($D$14+($E$14-$D$14)*(A23-$D$13)/($E$13-$D$13)),$E$14))))))) -> 0.37 | E23: =D23*F22 -> 0.1942056 | F23: =F22-E23 -> 0.3306744 | G23: =E23*$I$10 -> 0 | H23: =F23*$I$12 -> 0 | I23: =$J$12*(1-F23) -> 0 | N23: =(SUM(G23:K23)*B23)+(L23*C23) -> 0
A24: =A23+1 -> 4 | B24: =Metadata!C27 -> 0.87144223 | C24: =Metadata!G27 -> 0.94218423 | D24: =IF(A24<$B$13,$B$14,(IF(A24<$C$13,($B$14+($C$14-$B$14)*(A24-$B$13)/($C$13-$B$13)),(IF(A24<$D$13,($C$14+($D$14-$C$14)*(A24-$C$13)/($D$13-$C$13)),(IF(A24<$E$13,($D$14+($E$14-$D$14)*(A24-$D$13)/($E$13-$D$13)),$E$14))))))) -> 0.46 | E24: =D24*F23 -> 0.15211022 | F24: =F23-E24 -> 0.17856418 | G24: =E24*$I$10 -> 0 | H24: =F24*$I$12 -> 0 | I24: =$J$12*(1-F24) -> 0 | N24: =(SUM(G24:K24)*B24)+(L24*C24) -> 0
A25: =A24+1 -> 5 | B25: =Metadata!C28 -> 0.84197317 | C25: =Metadata!G28 -> 0.92826033 | D25: =IF(A25<$B$13,$B$14,(IF(A25<$C$13,($B$14+($C$14-$B$14)*(A25-$B$13)/($C$13-$B$13)),(IF(A25<$D$13,($C$14+($D$14-$C$14)*(A25-$C$13)/($D$13-$C$13)),(IF(A25<$E$13,($D$14+($E$14-$D$14)*(A25-$D$13)/($E$13-$D$13)),$E$14))))))) -> 0.55 | E25: =D25*F24 -> 0.098210297 | F25: =F24-E25 -> 0.080353879 | G25: =E25*$I$10 -> 0 | H25: =F25*$I$12 -> 0 | I25: =$J$12*(1-F25) -> 0 | N25: =(SUM(G25:K25)*B25)+(L25*C25) -> 0
A26: =A25+1 -> 6 | B26: =Metadata!C29 -> 0.81350064 | C26: =Metadata!G29 -> 0.91454219 | D26: =IF(A26<$B$13,$B$14,(IF(A26<$C$13,($B$14+($C$14-$B$14)*(A26-$B$13)/($C$13-$B$13)),(IF(A26<$D$13,($C$14+($D$14-$C$14)*(A26-$C$13)/($D$13-$C$13)),(IF(A26<$E$13,($D$14+($E$14-$D$14)*(A26-$D$13)/($E$13-$D$13)),$E$14))))))) -> 0.64 | E26: =D26*F25 -> 0.051426483 | F26: =F25-E26 -> 0.028927397 | G26: =E26*$I$10 -> 0 | H26: =F26*$I$12 -> 0 | I26: =$J$12*(1-F26) -> 0 | N26: =(SUM(G26:K26)*B26)+(L26*C26) -> 0
A27: =A26+1 -> 7 | B27: =Metadata!C30 -> 0.78599096 | C27: =Metadata!G30 -> 0.90102679 | D27: =IF(A27<$B$13,$B$14,(IF(A27<$C$13,($B$14+($C$14-$B$14)*(A27-$B$13)/($C$13-$B$13)),(IF(A27<$D$13,($C$14+($D$14-$C$14)*(A27-$C$13)/($D$13-$C$13)),(IF(A27<$E$13,($D$14+($E$14-$D$14)*(A27-$D$13)/($E$13-$D$13)),$E$14))))))) -> 0.73 | E27: =D27*F26 -> 0.021116999 | F27: =F26-E27 -> 0.0078103971 | G27: =E27*$I$10 -> 0 | H27: =F27*$I$12 -> 0 | I27: =$J$12*(1-F27) -> 0 | N27: =(SUM(G27:K27)*B27)+(L27*C27) -> 0
A28: =A27+1 -> 8 | B28: =Metadata!C31 -> 0.75941156 | C28: =Metadata!G31 -> 0.88771112 | D28: =IF(A28<$B$13,$B$14,(IF(A28<$C$13,($B$14+($C$14-$B$14)*(A28-$B$13)/($C$13-$B$13)),(IF(A28<$D$13,($C$14+($D$14-$C$14)*(A28-$C$13)/($D$13-$C$13)),(IF(A28<$E$13,($D$14+($E$14-$D$14)*(A28-$D$13)/($E$13-$D$13)),$E$14))))))) -> 0.82 | E28: =D28*F27 -> 0.0064045256 | F28: =F27-E28 -> 0.0014058715 | G28: =E28*$I$10 -> 0 | H28: =F28*$I$12 -> 0 | I28: =$J$12*(1-F28) -> 0 | N28: =(SUM(G28:K28)*B28)+(L28*C28) -> 0
A29: =A28+1 -> 9 | B29: =Metadata!C32 -> 0.73373097 | C29: =Metadata!G32 -> 0.87459224 | D29: =IF(A29<$B$13,$B$14,(IF(A29<$C$13,($B$14+($C$14-$B$14)*(A29-$B$13)/($C$13-$B$13)),(IF(A29<$D$13,($C$14+($D$14-$C$14)*(A29-$C$13)/($D$13-$C$13)),(IF(A29<$E$13,($D$14+($E$14-$D$14)*(A29-$D$13)/($E$13-$D$13)),$E$14))))))) -> 0.91 | E29: =D29*F28 -> 0.001279343 | F29: =F28-E29 -> 0.00012652843 | G29: =E29*$I$10 -> 0 | H29: =F29*$I$12 -> 0 | I29: =$J$12*(1-F29) -> 0 | N29: =(SUM(G29:K29)*B29)+(L29*C29) -> 0
A30: =A29+1 -> 10 | B30: =Metadata!C33 -> 0.70891881 | C30: =Metadata!G33 -> 0.86166723 | D30: =IF(A30<$B$13,$B$14,(IF(A30<$C$13,($B$14+($C$14-$B$14)*(A30-$B$13)/($C$13-$B$13)),(IF(A30<$D$13,($C$14+($D$14-$C$14)*(A30-$C$13)/($D$13-$C$13)),(IF(A30<$E$13,($D$14+($E$14-$D$14)*(A30-$D$13)/($E$13-$D$13)),$E$14))))))) -> 1 | E30: =D30*F29 -> 0.00012652843 | F30: =F29-E30 -> 0 | G30: =E30*$I$10 -> 0 | H30: =F30*$I$12 -> 0 | I30: =$J$12*(1-F30) -> 0 | N30: =(SUM(G30:K30)*B30)+(L30*C30) -> 0
A31: =A30+1 -> 11 | B31: =Metadata!C34 -> 0.68494571 | C31: =Metadata!G34 -> 0.84893323 | D31: =IF(A31<$B$13,$B$14,(IF(A31<$C$13,($B$14+($C$14-$B$14)*(A31-$B$13)/($C$13-$B$13)),(IF(A31<$D$13,($C$14+($D$14-$C$14)*(A31-$C$13)/($D$13-$C$13)),(IF(A31<$E$13,($D$14+($E$14-$D$14)*(A31-$D$13)/($E$13-$D$13)),$E$14))))))) -> 1 | E31: =D31*F30 -> 0 | F31: =F30-E31 -> 0 | G31: =E31*$I$10 -> 0 | H31: =F31*$I$12 -> 0 | I31: =$J$12*(1-F31) -> 0 | N31: =(SUM(G31:K31)*B31)+(L31*C31) -> 0
A32: =A31+1 -> 12 | B32: =Metadata!C35 -> 0.6617833 | C32: =Metadata!G35 -> 0.83638742 | D32: =IF(A32<$B$13,$B$14,(IF(A32<$C$13,($B$14+($C$14-$B$14)*(A32-$B$13)/($C$13-$B$13)),(IF(A32<$D$13,($C$14+($D$14-$C$14)*(A32-$C$13)/($D$13-$C$13)),(IF(A32<$E$13,($D$14+($E$14-$D$14)*(A32-$D$13)/($E$13-$D$13)),$E$14))))))) -> 1 | E32: =D32*F31 -> 0 | F32: =F31-E32 -> 0 | G32: =E32*$I$10 -> 0 | H32: =F32*$I$12 -> 0 | I32: =$J$12*(1-F32) -> 0 | N32: =(SUM(G32:K32)*B32)+(L32*C32) -> 0
... A119: =A118+1 -> 99 | B119: =Metadata!C122 -> 0.052088473 | C119: =Metadata!G122 -> 0.27877724 | D119: =IF(A119<$B$13,$B$14,(IF(A119<$C$13,($B$14+($C$14-$B$14)*(A119-$B$13)/($C$13-$B$13)),(IF(A119<$D$13,($C$14+($D$14-$C$14)*(A119-$C$13)/($D$13-$C$13)),(IF(A119<$E$13,($D$14+($E$14-$D$14)*(A119-$D$13)/($E$13-$D$13)),$E$14))))))) -> 1 | E119: =D119*F118 -> 0 | F119: =F118-E119 -> 0 | G119: =E119*$I$10 -> 0 | H119: =F119*$I$12 -> 0 | I119: =$J$12*(1-F119) -> 0 | N119: =(SUM(G119:K119)*B119)+(L119*C119) -> 0
A121: Total | G121: =SUM(G20:G119) -> 0 | H121: =SUM(H20:H119) -> 0 | N121: =SUM(N20:N119) -> 0
A123: Notes
A124: Complete one spreadsheet for each option which has a step change in rate of damage, for example, a breach.
A125: The formulae assume that breach probability will be constant to the first year entered and after the last year with linear variation between
A126: It is assumed that breaches are not repaired and that once breach damage has occurred it will not recur.
A127: A separate check should be made to ensure that overtopping damages do not exceed write off values.
A128: Remember to use the correct discount rate for the different sources of damage.
A129: If these assumptions are not valid then appropriate adjustments need to be made. Total damage is calculated as:
...

Sheet Erosion
D1: Erosion Loss Calculation Sheet with delay options | H1: Sheet Nr.
A2: Client/Authority
A3: =Summary!A3 -> 0
A4: Project name | D4: Option: | G4: Delay (yrs) | H4: Prepared (date) | J4: =Summary!F2 -> 44562
A5: =Summary!A5 -> 0 | D5: =Summary!A47 -> Do Nothing | G5: 0 | H5: Printed | J5: =Summary!F3 -> 44692
A6: Project reference | C6: =Summary!C6 -> 0 | D6: =Summary!A48 -> Do Minimum | G6: 10 | H6: Prepared by | J6: =Summary!F4 -> 0
A7: Base date for estimates (year 0) | C7: =Summary!C7 -> 44562 | D7: =Summary!A49 -> Option 3 | G7: 20 | H7: Checked by | J7: =Summary!F5 -> 0
A8: Scaling factor (e.g. £m, £k, £) | C8: =Summary!C8 -> £k | D8: =Summary!A50 -> Option 4 | G8: 30 | H8: Checked date | J8: =Summary!F6 -> 0
A9: Discount rate | C9: =Metadata!B23 -> 0.035 | D9: =Summary!A51 -> Option 5 | G9: 40
A10: Ref | B10: Asset | C10: Risk free market value | D10: Year when the asset is expected to be lost | E10: Prob of loss in year | H10: =CONCATENATE("PV Expected value of asset losses ",C8) -> PV Expected value of asset losses £k
B11: Description | C11: =C8 -> £k | F11: =Summary!A47 -> Do Nothing | G11: =Summary!A48 -> Do Minimum | H11: =Summary!A49 -> Option 3 | I11: =Summary!A50 -> Option 4 | J11: =Summary!A51 -> Option 5
F12: =$C12*$E12*VLOOKUP($D12,Metadata!$A$23:$C$123,3) -> 0 | G12: =IF($D$6="","",$C12*$E12*VLOOKUP($D12+$G$6,Metadata!$A$23:$C$123,3)) -> 0 | H12: =IF($D$7="","",$C12*$E12*VLOOKUP($D12+$G$7,Metadata!$A$23:$C$123,3)) -> 0 | I12: =IF($D$8="","",$C12*$E12*VLOOKUP($D12+$G$8,Metadata!$A$23:$C$123,3)) -> 0 | J12: =IF($D$9="","",$C12*$E12*VLOOKUP($D12+$G$9,Metadata!$A$23:$C$123,3)) -> 0
F13: =$C13*$E13*VLOOKUP($D13,Metadata!$A$23:$C$123,3) -> 0 | G13: =IF($D$6="","",$C13*$E13*VLOOKUP($D13+$G$6,Metadata!$A$23:$C$123,3)) -> 0 | H13: =IF($D$7="","",$C13*$E13*VLOOKUP($D13+$G$7,Metadata!$A$23:$C$123,3)) -> 0 | I13: =IF($D$8="","",$C13*$E13*VLOOKUP($D13+$G$8,Metadata!$A$23:$C$123,3)) -> 0 | J13: =IF($D$9="","",$C13*$E13*VLOOKUP($D13+$G$9,Metadata!$A$23:$C$123,3)) -> 0
F14: =$C14*$E14*VLOOKUP($D14,Metadata!$A$23:$C$123,3) -> 0 | G14: =IF($D$6="","",$C14*$E14*VLOOKUP($D14+$G$6,Metadata!$A$23:$C$123,3)) -> 0 | H14: =IF($D$7="","",$C14*$E14*VLOOKUP($D14+$G$7,Metadata!$A$23:$C$123,3)) -> 0 | I14: =IF($D$8="","",$C14*$E14*VLOOKUP($D14+$G$8,Metadata!$A$23:$C$123,3)) -> 0 | J14: =IF($D$9="","",$C14*$E14*VLOOKUP($D14+$G$9,Metadata!$A$23:$C$123,3)) -> 0
F15: =$C15*$E15*VLOOKUP($D15,Metadata!$A$23:$C$123,3) -> 0 | G15: =IF($D$6="","",$C15*$E15*VLOOKUP($D15+$G$6,Metadata!$A$23:$C$123,3)) -> 0 | H15: =IF($D$7="","",$C15*$E15*VLOOKUP($D15+$G$7,Metadata!$A$23:$C$123,3)) -> 0 | I15: =IF($D$8="","",$C15*$E15*VLOOKUP($D15+$G$8,Metadata!$A$23:$C$123,3)) -> 0 | J15: =IF($D$9="","",$C15*$E15*VLOOKUP($D15+$G$9,Metadata!$A$23:$C$123,3)) -> 0
F16: =$C16*$E16*VLOOKUP($D16,Metadata!$A$23:$C$123,3) -> 0 | G16: =IF($D$6="","",$C16*$E16*VLOOKUP($D16+$G$6,Metadata!$A$23:$C$123,3)) -> 0 | H16: =IF($D$7="","",$C16*$E16*VLOOKUP($D16+$G$7,Metadata!$A$23:$C$123,3)) -> 0 | I16: =IF($D$8="","",$C16*$E16*VLOOKUP($D16+$G$8,Metadata!$A$23:$C$123,3)) -> 0 | J16: =IF($D$9="","",$C16*$E16*VLOOKUP($D16+$G$9,Metadata!$A$23:$C$123,3)) -> 0
F17: =$C17*$E17*VLOOKUP($D17,Metadata!$A$23:$C$123,3) -> 0 | G17: =IF($D$6="","",$C17*$E17*VLOOKUP($D17+$G$6,Metadata!$A$23:$C$123,3)) -> 0 | H17: =IF($D$7="","",$C17*$E17*VLOOKUP($D17+$G$7,Metadata!$A$23:$C$123,3)) -> 0 | I17: =IF($D$8="","",$C17*$E17*VLOOKUP($D17+$G$8,Metadata!$A$23:$C$123,3)) -> 0 | J17: =IF($D$9="","",$C17*$E17*VLOOKUP($D17+$G$9,Metadata!$A$23:$C$123,3)) -> 0
F18: =$C18*$E18*VLOOKUP($D18,Metadata!$A$23:$C$123,3) -> 0 | G18: =IF($D$6="","",$C18*$E18*VLOOKUP($D18+$G$6,Metadata!$A$23:$C$123,3)) -> 0 | H18: =IF($D$7="","",$C18*$E18*VLOOKUP($D18+$G$7,Metadata!$A$23:$C$123,3)) -> 0 | I18: =IF($D$8="","",$C18*$E18*VLOOKUP($D18+$G$8,Metadata!$A$23:$C$123,3)) -> 0 | J18: =IF($D$9="","",$C18*$E18*VLOOKUP($D18+$G$9,Metadata!$A$23:$C$123,3)) -> 0
F19: =$C19*$E19*VLOOKUP($D19,Metadata!$A$23:$C$123,3) -> 0 | G19: =IF($D$6="","",$C19*$E19*VLOOKUP($D19+$G$6,Metadata!$A$23:$C$123,3)) -> 0 | H19: =IF($D$7="","",$C19*$E19*VLOOKUP($D19+$G$7,Metadata!$A$23:$C$123,3)) -> 0 | I19: =IF($D$8="","",$C19*$E19*VLOOKUP($D19+$G$8,Metadata!$A$23:$C$123,3)) -> 0 | J19: =IF($D$9="","",$C19*$E19*VLOOKUP($D19+$G$9,Metadata!$A$23:$C$123,3)) -> 0
F20: =$C20*$E20*VLOOKUP($D20,Metadata!$A$23:$C$123,3) -> 0 | G20: =IF($D$6="","",$C20*$E20*VLOOKUP($D20+$G$6,Metadata!$A$23:$C$123,3)) -> 0 | H20: =IF($D$7="","",$C20*$E20*VLOOKUP($D20+$G$7,Metadata!$A$23:$C$123,3)) -> 0 | I20: =IF($D$8="","",$C20*$E20*VLOOKUP($D20+$G$8,Metadata!$A$23:$C$123,3)) -> 0 | J20: =IF($D$9="","",$C20*$E20*VLOOKUP($D20+$G$9,Metadata!$A$23:$C$123,3)) -> 0
F21: =$C21*$E21*VLOOKUP($D21,Metadata!$A$23:$C$123,3) -> 0 | G21: =IF($D$6="","",$C21*$E21*VLOOKUP($D21+$G$6,Metadata!$A$23:$C$123,3)) -> 0 | H21: =IF($D$7="","",$C21*$E21*VLOOKUP($D21+$G$7,Metadata!$A$23:$C$123,3)) -> 0 | I21: =IF($D$8="","",$C21*$E21*VLOOKUP($D21+$G$8,Metadata!$A$23:$C$123,3)) -> 0 | J21: =IF($D$9="","",$C21*$E21*VLOOKUP($D21+$G$9,Metadata!$A$23:$C$123,3)) -> 0
F22: =$C22*$E22*VLOOKUP($D22,Metadata!$A$23:$C$123,3) -> 0 | G22: =IF($D$6="","",$C22*$E22*VLOOKUP($D22+$G$6,Metadata!$A$23:$C$123,3)) -> 0 | H22: =IF($D$7="","",$C22*$E22*VLOOKUP($D22+$G$7,Metadata!$A$23:$C$123,3)) -> 0 | I22: =IF($D$8="","",$C22*$E22*VLOOKUP($D22+$G$8,Metadata!$A$23:$C$123,3)) -> 0 | J22: =IF($D$9="","",$C22*$E22*VLOOKUP($D22+$G$9,Metadata!$A$23:$C$123,3)) -> 0
F23: =$C23*$E23*VLOOKUP($D23,Metadata!$A$23:$C$123,3) -> 0 | G23: =IF($D$6="","",$C23*$E23*VLOOKUP($D23+$G$6,Metadata!$A$23:$C$123,3)) -> 0 | H23: =IF($D$7="","",$C23*$E23*VLOOKUP($D23+$G$7,Metadata!$A$23:$C$123,3)) -> 0 | I23: =IF($D$8="","",$C23*$E23*VLOOKUP($D23+$G$8,Metadata!$A$23:$C$123,3)) -> 0 | J23: =IF($D$9="","",$C23*$E23*VLOOKUP($D23+$G$9,Metadata!$A$23:$C$123,3)) -> 0
... F62: =$C62*$E62*VLOOKUP($D62,Metadata!$A$23:$C$123,3) -> 0 | G62: =IF($D$6="","",$C62*$E62*VLOOKUP($D62+$G$6,Metadata!$A$23:$C$123,3)) -> 0 | H62: =IF($D$7="","",$C62*$E62*VLOOKUP($D62+$G$7,Metadata!$A$23:$C$123,3)) -> 0 | I62: =IF($D$8="","",$C62*$E62*VLOOKUP($D62+$G$8,Metadata!$A$23:$C$123,3)) -> 0 | J62: =IF($D$9="","",$C62*$E62*VLOOKUP($D62+$G$9,Metadata!$A$23:$C$123,3)) -> 0
A64: Totals | C64: {=SUM(IF($B$12:$B$62="",0,$C$12:$C$62))} -> 0 | F64: =SUM(F12:F63) -> 0 | G64: =IF($D$5="","",SUM(G12:G63)) -> 0 | H64: =IF($D$6="","",SUM(H12:H63)) -> 0 | I64: =IF($D$7="","",SUM(I12:I63)) -> 0 | J64: =IF($D$8="","",SUM(J12:J63)) -> 0
A66: Notes
A67: Make one entry in the description column for each property (or group of properties) as this determines subsequent calculation
A68: MV = risk free market value at base date for estimate - must be entered on each line when probaility distribution is used
A69: Equivalent annual value = MV x discount rate (assumes infinite life)
A70: Year is year in which there is the probability of loss shown, years must be entered consecutively for each property or group
A71: If no distribution is used enter year of expected year of loss and enter 1.0 in probability column
A72: Columns G to K show expected values of asset losses with each option, assuming extensions of life entered above
A73: The loss is calculated using the formula PV loss = MV * Prob of loss * (1 - (1 - 1/((1+r)^(Year of loss))) = MV * Prob of loss / ((1+r)^(Year of loss))
A74: Additional properties can be entered by inserting lines above line 62 and copying all formulae

Sheet PV Costs
N1: Present Value Costs for all options | AE1: Sheet Nr.
A2: Client/Authority
A3: =Summary!A3 -> 0
A4: Project name | L4: =CONCATENATE("Results ",D8) -> Results £k | AE4: Prepared (date) | AH4: =Summary!F2 -> 44562
A5: =Summary!A5 -> 0 | AE5: Printed | AH5: =Summary!F3 -> 44692
A6: Project reference | D6: =Summary!C6 -> 0 | AE6: Prepared by | AH6: =Summary!F4 -> 0
A7: Base date for estimates (year 0) | D7: =Summary!C7 -> 44562 | N7: =$D$10 -> Do Nothing | P7: =$M$10 -> Do Minimum | R7: =$V$10 -> Option 3 | T7: =$AE$10 -> Option 4 | V7: =AN10 -> Option 5 | AE7: Checked by | AH7: =Summary!F5 -> 0
A8: Scaling factor (e.g. £m, £k, £) | D8: =Summary!C8 -> £k | L8: PV total costs | N8: =SUM(H12:K12) -> 0 | P8: =SUM(Q12:T12) -> 0 | R8: =SUM(Z12:AC12) -> 0 | T8: =SUM(AI12:AL12) -> 0 | V8: =SUM(AR12:AU12) -> 0 | AE8: Checked date | AH8: =Summary!F6 -> 0
A9: Initial discount rate | D9: =Metadata!B23 -> 0.035
D10: =Summary!A47 -> Do Nothing | G10: TOTALS: | H10: PV | I10: PV | J10: PV | K10: PV | M10: =Summary!A48 -> Do Minimum | P10: TOTALS: | Q10: PV | R10: PV | S10: PV | T10: PV | V10: =Summary!A49 -> Option 3 | Y10: TOTALS: | Z10: PV | AA10: PV | AB10: PV | AC10: PV | AE10: =Summary!A50 -> Option 4 | AH10: TOTALS: | AI10: PV | AJ10: PV | AK10: PV | AL10: PV | AN10: =Summary!A51 -> Option 5 | AQ10: TOTALS: | AR10: PV | AS10: PV | AT10: PV | AU10: PV
C11: Capital | D11: Maint. | E11: Other | F11: Negative costs | G11: Cash | H11: Capital | I11: Maint | J11: Other | K11: Negative costs | L11: Capital | M11: Maint. | N11: Other | O11: Negative costs | P11: Cash | Q11: Capital | R11: Maint | S11: Other | T11: Negative costs | U11: Capital | V11: Maint. | W11: Other | X11: Negative costs | Y11: Cash | Z11: Capital | AA11: Maint | AB11: Other | AC11: Negative costs | AD11: Capital | AE11: Maint. | AF11: Other | AG11: Negative costs | AH11: Cash | AI11: Capital | AJ11: Maint | AK11: Other | AL11: Negative costs | AM11: Capital | AN11: Maint. | AO11: Other | AP11: Negative costs | AQ11: Cash | AR11: Capital | AS11: Maint | AT11: Other | AU11: Negative costs
B12: cash sum | C12: =SUM(C15:C114) -> 0 | D12: =SUM(D15:D114) -> 0 | E12: =SUM(E15:E114) -> 0 | F12: =SUM(F15:F114) -> 0 | G12: =SUM(G15:G114) -> 0 | H12: =SUM(H15:H114) -> 0 | I12: =SUM(I15:I114) -> 0 | J12: =SUM(J15:J114) -> 0 | ... AU12: =SUM(AU15:AU114) -> 0
B13: Discount
A14: year | B14: Factor
A15: 0 | B15: =Metadata!C23 -> 1 | G15: =SUM(C15:F15) -> 0 | H15: =C15*$B15 -> 0 | I15: =D15*$B15 -> 0 | J15: =E15*$B15 -> 0 | K15: =F15*$B15 -> 0 | P15: =SUM(L15:O15) -> 0 | Q15: =L15*$B15 -> 0 | R15: =M15*$B15 -> 0 | S15: =N15*$B15 -> 0 | T15: =O15*$B15 -> 0 | Y15: =SUM(U15:X15) -> 0 | Z15: =U15*$B15 -> 0 | AA15: =V15*$B15 -> 0 | AB15: =W15*$B15 -> 0 | AC15: =X15*$B15 -> 0 | AH15: =SUM(AD15:AG15) -> 0 | AI15: =AD15*$B15 -> 0 | AJ15: =AE15*$B15 -> 0 | AK15: =AF15*$B15 -> 0 | AL15: =AG15*$B15 -> 0 | AQ15: =SUM(AM15:AP15) -> 0 | AR15: =AM15*$B15 -> 0 | AS15: =AN15*$B15 -> 0 | AT15: =AO15*$B15 -> 0 | AU15: =AP15*$B15 -> 0
A16: =A15+1 -> 1 | B16: =Metadata!C24 -> 0.96618357 | G16: =SUM(C16:F16) -> 0 | H16: =C16*$B16 -> 0 | I16: =D16*$B16 -> 0 | J16: =E16*$B16 -> 0 | K16: =F16*$B16 -> 0 | P16: =SUM(L16:O16) -> 0 | Q16: =L16*$B16 -> 0 | R16: =M16*$B16 -> 0 | S16: =N16*$B16 -> 0 | T16: =O16*$B16 -> 0 | Y16: =SUM(U16:X16) -> 0 | Z16: =U16*$B16 -> 0 | AA16: =V16*$B16 -> 0 | AB16: =W16*$B16 -> 0 | AC16: =X16*$B16 -> 0 | AH16: =SUM(AD16:AG16) -> 0 | AI16: =AD16*$B16 -> 0 | AJ16: =AE16*$B16 -> 0 | AK16: =AF16*$B16 -> 0 | AL16: =AG16*$B16 -> 0 | AQ16: =SUM(AM16:AP16) -> 0 | AR16: =AM16*$B16 -> 0 | AS16: =AN16*$B16 -> 0 | AT16: =AO16*$B16 -> 0 | AU16: =AP16*$B16 -> 0
A17: =A16+1 -> 2 | B17: =Metadata!C25 -> 0.9335107 | G17: =SUM(C17:F17) -> 0 | H17: =C17*$B17 -> 0 | I17: =D17*$B17 -> 0 | J17: =E17*$B17 -> 0 | K17: =F17*$B17 -> 0 | P17: =SUM(L17:O17) -> 0 | Q17: =L17*$B17 -> 0 | R17: =M17*$B17 -> 0 | S17: =N17*$B17 -> 0 | T17: =O17*$B17 -> 0 | Y17: =SUM(U17:X17) -> 0 | Z17: =U17*$B17 -> 0 | AA17: =V17*$B17 -> 0 | AB17: =W17*$B17 -> 0 | AC17: =X17*$B17 -> 0 | AH17: =SUM(AD17:AG17) -> 0 | AI17: =AD17*$B17 -> 0 | AJ17: =AE17*$B17 -> 0 | AK17: =AF17*$B17 -> 0 | AL17: =AG17*$B17 -> 0 | AQ17: =SUM(AM17:AP17) -> 0 | AR17: =AM17*$B17 -> 0 | AS17: =AN17*$B17 -> 0 | AT17: =AO17*$B17 -> 0 | AU17: =AP17*$B17 -> 0
A18: =A17+1 -> 3 | B18: =Metadata!C26 -> 0.90194271 | G18: =SUM(C18:F18) -> 0 | H18: =C18*$B18 -> 0 | I18: =D18*$B18 -> 0 | J18: =E18*$B18 -> 0 | K18: =F18*$B18 -> 0 | P18: =SUM(L18:O18) -> 0 | Q18: =L18*$B18 -> 0 | R18: =M18*$B18 -> 0 | S18: =N18*$B18 -> 0 | T18: =O18*$B18 -> 0 | Y18: =SUM(U18:X18) -> 0 | Z18: =U18*$B18 -> 0 | AA18: =V18*$B18 -> 0 | AB18: =W18*$B18 -> 0 | AC18: =X18*$B18 -> 0 | AH18: =SUM(AD18:AG18) -> 0 | AI18: =AD18*$B18 -> 0 | AJ18: =AE18*$B18 -> 0 | AK18: =AF18*$B18 -> 0 | AL18: =AG18*$B18 -> 0 | AQ18: =SUM(AM18:AP18) -> 0 | AR18: =AM18*$B18 -> 0 | AS18: =AN18*$B18 -> 0 | AT18: =AO18*$B18 -> 0 | AU18: =AP18*$B18 -> 0
A19: =A18+1 -> 4 | B19: =Metadata!C27 -> 0.87144223 | G19: =SUM(C19:F19) -> 0 | H19: =C19*$B19 -> 0 | I19: =D19*$B19 -> 0 | J19: =E19*$B19 -> 0 | K19: =F19*$B19 -> 0 | P19: =SUM(L19:O19) -> 0 | Q19: =L19*$B19 -> 0 | R19: =M19*$B19 -> 0 | S19: =N19*$B19 -> 0 | T19: =O19*$B19 -> 0 | Y19: =SUM(U19:X19) -> 0 | Z19: =U19*$B19 -> 0 | AA19: =V19*$B19 -> 0 | AB19: =W19*$B19 -> 0 | AC19: =X19*$B19 -> 0 | AH19: =SUM(AD19:AG19) -> 0 | AI19: =AD19*$B19 -> 0 | AJ19: =AE19*$B19 -> 0 | AK19: =AF19*$B19 -> 0 | AL19: =AG19*$B19 -> 0 | AQ19: =SUM(AM19:AP19) -> 0 | AR19: =AM19*$B19 -> 0 | AS19: =AN19*$B19 -> 0 | AT19: =AO19*$B19 -> 0 | AU19: =AP19*$B19 -> 0
A20: =A19+1 -> 5 | B20: =Metadata!C28 -> 0.84197317 | G20: =SUM(C20:F20) -> 0 | H20: =C20*$B20 -> 0 | I20: =D20*$B20 -> 0 | J20: =E20*$B20 -> 0 | K20: =F20*$B20 -> 0 | P20: =SUM(L20:O20) -> 0 | Q20: =L20*$B20 -> 0 | R20: =M20*$B20 -> 0 | S20: =N20*$B20 -> 0 | T20: =O20*$B20 -> 0 | Y20: =SUM(U20:X20) -> 0 | Z20: =U20*$B20 -> 0 | AA20: =V20*$B20 -> 0 | AB20: =W20*$B20 -> 0 | AC20: =X20*$B20 -> 0 | AH20: =SUM(AD20:AG20) -> 0 | AI20: =AD20*$B20 -> 0 | AJ20: =AE20*$B20 -> 0 | AK20: =AF20*$B20 -> 0 | AL20: =AG20*$B20 -> 0 | AQ20: =SUM(AM20:AP20) -> 0 | AR20: =AM20*$B20 -> 0 | AS20: =AN20*$B20 -> 0 | AT20: =AO20*$B20 -> 0 | AU20: =AP20*$B20 -> 0
A21: =A20+1 -> 6 | B21: =Metadata!C29 -> 0.81350064 | G21: =SUM(C21:F21) -> 0 | H21: =C21*$B21 -> 0 | I21: =D21*$B21 -> 0 | J21: =E21*$B21 -> 0 | K21: =F21*$B21 -> 0 | P21: =SUM(L21:O21) -> 0 | Q21: =L21*$B21 -> 0 | R21: =M21*$B21 -> 0 | S21: =N21*$B21 -> 0 | T21: =O21*$B21 -> 0 | Y21: =SUM(U21:X21) -> 0 | Z21: =U21*$B21 -> 0 | AA21: =V21*$B21 -> 0 | AB21: =W21*$B21 -> 0 | AC21: =X21*$B21 -> 0 | AH21: =SUM(AD21:AG21) -> 0 | AI21: =AD21*$B21 -> 0 | AJ21: =AE21*$B21 -> 0 | AK21: =AF21*$B21 -> 0 | AL21: =AG21*$B21 -> 0 | AQ21: =SUM(AM21:AP21) -> 0 | AR21: =AM21*$B21 -> 0 | AS21: =AN21*$B21 -> 0 | AT21: =AO21*$B21 -> 0 | AU21: =AP21*$B21 -> 0
A22: =A21+1 -> 7 | B22: =Metadata!C30 -> 0.78599096 | G22: =SUM(C22:F22) -> 0 | H22: =C22*$B22 -> 0 | I22: =D22*$B22 -> 0 | J22: =E22*$B22 -> 0 | K22: =F22*$B22 -> 0 | P22: =SUM(L22:O22) -> 0 | Q22: =L22*$B22 -> 0 | R22: =M22*$B22 -> 0 | S22: =N22*$B22 -> 0 | T22: =O22*$B22 -> 0 | Y22: =SUM(U22:X22) -> 0 | Z22: =U22*$B22 -> 0 | AA22: =V22*$B22 -> 0 | AB22: =W22*$B22 -> 0 | AC22: =X22*$B22 -> 0 | AH22: =SUM(AD22:AG22) -> 0 | AI22: =AD22*$B22 -> 0 | AJ22: =AE22*$B22 -> 0 | AK22: =AF22*$B22 -> 0 | AL22: =AG22*$B22 -> 0 | AQ22: =SUM(AM22:AP22) -> 0 | AR22: =AM22*$B22 -> 0 | AS22: =AN22*$B22 -> 0 | AT22: =AO22*$B22 -> 0 | AU22: =AP22*$B22 -> 0
A23: =A22+1 -> 8 | B23: =Metadata!C31 -> 0.75941156 | G23: =SUM(C23:F23) -> 0 | H23: =C23*$B23 -> 0 | I23: =D23*$B23 -> 0 | J23: =E23*$B23 -> 0 | K23: =F23*$B23 -> 0 | P23: =SUM(L23:O23) -> 0 | Q23: =L23*$B23 -> 0 | R23: =M23*$B23 -> 0 | S23: =N23*$B23 -> 0 | T23: =O23*$B23 -> 0 | Y23: =SUM(U23:X23) -> 0 | Z23: =U23*$B23 -> 0 | AA23: =V23*$B23 -> 0 | AB23: =W23*$B23 -> 0 | AC23: =X23*$B23 -> 0 | AH23: =SUM(AD23:AG23) -> 0 | AI23: =AD23*$B23 -> 0 | AJ23: =AE23*$B23 -> 0 | AK23: =AF23*$B23 -> 0 | AL23: =AG23*$B23 -> 0 | AQ23: =SUM(AM23:AP23) -> 0 | AR23: =AM23*$B23 -> 0 | AS23: =AN23*$B23 -> 0 | AT23: =AO23*$B23 -> 0 | AU23: =AP23*$B23 -> 0
A24: =A23+1 -> 9 | B24: =Metadata!C32 -> 0.73373097 | G24: =SUM(C24:F24) -> 0 | H24: =C24*$B24 -> 0 | I24: =D24*$B24 -> 0 | J24: =E24*$B24 -> 0 | K24: =F24*$B24 -> 0 | P24: =SUM(L24:O24) -> 0 | Q24: =L24*$B24 -> 0 | R24: =M24*$B24 -> 0 | S24: =N24*$B24 -> 0 | T24: =O24*$B24 -> 0 | Y24: =SUM(U24:X24) -> 0 | Z24: =U24*$B24 -> 0 | AA24: =V24*$B24 -> 0 | AB24: =W24*$B24 -> 0 | AC24: =X24*$B24 -> 0 | AH24: =SUM(AD24:AG24) -> 0 | AI24: =AD24*$B24 -> 0 | AJ24: =AE24*$B24 -> 0 | AK24: =AF24*$B24 -> 0 | AL24: =AG24*$B24 -> 0 | AQ24: =SUM(AM24:AP24) -> 0 | AR24: =AM24*$B24 -> 0 | AS24: =AN24*$B24 -> 0 | AT24: =AO24*$B24 -> 0 | AU24: =AP24*$B24 -> 0
A25: =A24+1 -> 10 | B25: =Metadata!C33 -> 0.70891881 | G25: =SUM(C25:F25) -> 0 | H25: =C25*$B25 -> 0 | I25: =D25*$B25 -> 0 | J25: =E25*$B25 -> 0 | K25: =F25*$B25 -> 0 | P25: =SUM(L25:O25) -> 0 | Q25: =L25*$B25 -> 0 | R25: =M25*$B25 -> 0 | S25: =N25*$B25 -> 0 | T25: =O25*$B25 -> 0 | Y25: =SUM(U25:X25) -> 0 | Z25: =U25*$B25 -> 0 | AA25: =V25*$B25 -> 0 | AB25: =W25*$B25 -> 0 | AC25: =X25*$B25 -> 0 | AH25: =SUM(AD25:AG25) -> 0 | AI25: =AD25*$B25 -> 0 | AJ25: =AE25*$B25 -> 0 | AK25: =AF25*$B25 -> 0 | AL25: =AG25*$B25 -> 0 | AQ25: =SUM(AM25:AP25) -> 0 | AR25: =AM25*$B25 -> 0 | AS25: =AN25*$B25 -> 0 | AT25: =AO25*$B25 -> 0 | AU25: =AP25*$B25 -> 0
A26: =A25+1 -> 11 | B26: =Metadata!C34 -> 0.68494571 | G26: =SUM(C26:F26) -> 0 | H26: =C26*$B26 -> 0 | I26: =D26*$B26 -> 0 | J26: =E26*$B26 -> 0 | K26: =F26*$B26 -> 0 | P26: =SUM(L26:O26) -> 0 | Q26: =L26*$B26 -> 0 | R26: =M26*$B26 -> 0 | S26: =N26*$B26 -> 0 | T26: =O26*$B26 -> 0 | Y26: =SUM(U26:X26) -> 0 | Z26: =U26*$B26 -> 0 | AA26: =V26*$B26 -> 0 | AB26: =W26*$B26 -> 0 | AC26: =X26*$B26 -> 0 | AH26: =SUM(AD26:AG26) -> 0 | AI26: =AD26*$B26 -> 0 | AJ26: =AE26*$B26 -> 0 | AK26: =AF26*$B26 -> 0 | AL26: =AG26*$B26 -> 0 | AQ26: =SUM(AM26:AP26) -> 0 | AR26: =AM26*$B26 -> 0 | AS26: =AN26*$B26 -> 0 | AT26: =AO26*$B26 -> 0 | AU26: =AP26*$B26 -> 0
A27: =A26+1 -> 12 | B27: =Metadata!C35 -> 0.6617833 | G27: =SUM(C27:F27) -> 0 | H27: =C27*$B27 -> 0 | I27: =D27*$B27 -> 0 | J27: =E27*$B27 -> 0 | K27: =F27*$B27 -> 0 | P27: =SUM(L27:O27) -> 0 | Q27: =L27*$B27 -> 0 | R27: =M27*$B27 -> 0 | S27: =N27*$B27 -> 0 | T27: =O27*$B27 -> 0 | Y27: =SUM(U27:X27) -> 0 | Z27: =U27*$B27 -> 0 | AA27: =V27*$B27 -> 0 | AB27: =W27*$B27 -> 0 | AC27: =X27*$B27 -> 0 | AH27: =SUM(AD27:AG27) -> 0 | AI27: =AD27*$B27 -> 0 | AJ27: =AE27*$B27 -> 0 | AK27: =AF27*$B27 -> 0 | AL27: =AG27*$B27 -> 0 | AQ27: =SUM(AM27:AP27) -> 0 | AR27: =AM27*$B27 -> 0 | AS27: =AN27*$B27 -> 0 | AT27: =AO27*$B27 -> 0 | AU27: =AP27*$B27 -> 0
... A114: =A113+1 -> 99 | B114: =Metadata!C122 -> 0.052088473 | G114: =SUM(C114:F114) -> 0 | H114: =C114*$B114 -> 0 | I114: =D114*$B114 -> 0 | J114: =E114*$B114 -> 0 | K114: =F114*$B114 -> 0 | P114: =SUM(L114:O114) -> 0 | Q114: =L114*$B114 -> 0 | R114: =M114*$B114 -> 0 | S114: =N114*$B114 -> 0 | T114: =O114*$B114 -> 0 | Y114: =SUM(U114:X114) -> 0 | Z114: =U114*$B114 -> 0 | AA114: =V114*$B114 -> 0 | AB114: =W114*$B114 -> 0 | AC114: =X114*$B114 -> 0 | AH114: =SUM(AD114:AG114) -> 0 | AI114: =AD114*$B114 -> 0 | AJ114: =AE114*$B114 -> 0 | AK114: =AF114*$B114 -> 0 | AL114: =AG114*$B114 -> 0 | AQ114: =SUM(AM114:AP114) -> 0 | AR114: =AM114*$B114 -> 0 | AS114: =AN114*$B114 -> 0 | AT114: =AO114*$B114 -> 0 | AU114: =AP114*$B114 -> 0

Sheet PV Damages
O1: Present Value Damages or Benefits | S1: Use this sheet to apply discounting and interpolation to any source of damages or benefits | AF1: Sheet Nr.
A2: Client/Authority | S2: Note: apply the correct discount rate for each source of damage
A3: =Summary!A3 -> 0
A4: Project name | M4: =CONCATENATE("Results ",E8) -> Results £k | AF4: Prepared (date) | AI4: =Summary!F2 -> 44562
A5: =Summary!A5 -> 0 | AF5: Printed | AI5: =Summary!F3 -> 44692
A6: Project reference | E6: =Summary!C6 -> 0 | AF6: Prepared by | AI6: =Summary!F4 -> 0
A7: Base date for estimates (year 0) | E7: =Summary!C7 -> 44562 | O7: =$E$10 -> Do Nothing | Q7: =$N$10 -> Do Minimum | S7: =$W$10 -> Option 3 | U7: =$AF$10 -> Option 4 | W7: =AO10 -> Option 5 | AF7: Checked by | AI7: =Summary!F5 -> 0
A8: Scaling factor (e.g. £m, £k, £) | E8: =Summary!C8 -> £k | M8: PV total costs | O8: =SUM(I12:L12) -> 0 | Q8: =SUM(R12:U12) -> 0 | S8: =SUM(AA12:AD12) -> 0 | U8: =SUM(AJ12:AM12) -> 0 | W8: =SUM(AS12:AV12) -> 0 | AF8: Checked date | AI8: =Summary!F6 -> 0
A9: Initial discount rate
E10: =Summary!A47 -> Do Nothing | H10: TOTALS: | I10: PV | J10: PV | K10: PV | L10: PV | N10: =Summary!A48 -> Do Minimum | Q10: TOTALS: | R10: PV | S10: PV | T10: PV | U10: PV | W10: =Summary!A49 -> Option 3 | Z10: TOTALS: | AA10: PV | AB10: PV | AC10: PV | AD10: PV | AF10: =Summary!A50 -> Option 4 | AI10: TOTALS: | AJ10: PV | AK10: PV | AL10: PV | AM10: PV | AO10: =Summary!A51 -> Option 5 | AR10: TOTALS: | AS10: PV | AT10: PV | AU10: PV | AV10: PV
D11: Damage 1 | E11: Damage 2 | F11: Damage 3 | G11: Life and Health Damage | H11: Cash | I11: Damage 1 | J11: Damage 2 | K11: Damage 3 | L11: Life and Health Damage | M11: Damage 1 | N11: Damage 2 | O11: Damage 3 | P11: Life and Health Damage | Q11: Cash | R11: Damage 1 | S11: Damage 2 | T11: Damage 3 | U11: Life and Health Damage | V11: Damage 1 | W11: Damage 2 | X11: Damage 3 | Y11: Life and Health Damage | Z11: Cash | AA11: Damage 1 | AB11: Damage 2 | AC11: Damage 3 | AD11: Life and Health Damage | AE11: Damage 1 | AF11: Damage 2 | AG11: Damage 3 | AH11: Life and Health Damage | AI11: Cash | AJ11: Damage 1 | AK11: Damage 2 | AL11: Damage 3 | AM11: Life and Health Damage | AN11: Damage 1 | AO11: Damage 2 | AP11: Damage 3 | AQ11: Life and Health Damage | AR11: Cash | AS11: Damage 1 | AT11: Damage 2 | AU11: Damage 3 | AV11: Life and Health Damage
B12: cash sum | D12: =SUM(D15:D114) -> 0 | E12: =SUM(E15:E114) -> 0 | F12: =SUM(F15:F114) -> 0 | G12: =SUM(G15:G114) -> 0 | H12: =SUM(H15:H114) -> 0 | I12: =SUM(I15:I114) -> 0 | J12: =SUM(J15:J114) -> 0 | K12: =SUM(K15:K114) -> 0 | ... AV12: =SUM(AV15:AV114) -> 0
B13: Standard Discount | C13: Health Discount
A14: year | B14: Factor | C14: Factor
A15: 0 | B15: =Metadata!C23 -> 1 | C15: =Metadata!G23 -> 1 | H15: =SUM(D15:G15) -> 0 | I15: =D15*$B15 -> 0 | J15: =E15*$B15 -> 0 | K15: =F15*$B15 -> 0 | L15: =G15*$C15 -> 0 | Q15: =SUM(M15:P15) -> 0 | R15: =M15*$B15 -> 0 | S15: =N15*$B15 -> 0 | T15: =O15*$B15 -> 0 | U15: =P15*$C15 -> 0 | Z15: =SUM(V15:Y15) -> 0 | AA15: =V15*$B15 -> 0 | AB15: =W15*$B15 -> 0 | AC15: =X15*$B15 -> 0 | AD15: =Y15*$C15 -> 0 | AI15: =SUM(AE15:AH15) -> 0 | AJ15: =AE15*$B15 -> 0 | AK15: =AF15*$B15 -> 0 | AL15: =AG15*$B15 -> 0 | AM15: =AH15*$C15 -> 0 | AR15: =SUM(AN15:AQ15) -> 0 | AS15: =AN15*$B15 -> 0 | AT15: =AO15*$B15 -> 0 | AU15: =AP15*$B15 -> 0 | AV15: =AQ15*$C15 -> 0
A16: =A15+1 -> 1 | B16: =Metadata!C24 -> 0.96618357 | C16: =Metadata!G24 -> 0.98522167 | H16: =SUM(D16:G16) -> 0 | I16: =D16*$B16 -> 0 | J16: =E16*$B16 -> 0 | K16: =F16*$B16 -> 0 | L16: =G16*$C16 -> 0 | Q16: =SUM(M16:P16) -> 0 | R16: =M16*$B16 -> 0 | S16: =N16*$B16 -> 0 | T16: =O16*$B16 -> 0 | U16: =P16*$C16 -> 0 | Z16: =SUM(V16:Y16) -> 0 | AA16: =V16*$B16 -> 0 | AB16: =W16*$B16 -> 0 | AC16: =X16*$B16 -> 0 | AD16: =Y16*$C16 -> 0 | AI16: =SUM(AE16:AH16) -> 0 | AJ16: =AE16*$B16 -> 0 | AK16: =AF16*$B16 -> 0 | AL16: =AG16*$B16 -> 0 | AM16: =AH16*$C16 -> 0 | AR16: =SUM(AN16:AQ16) -> 0 | AS16: =AN16*$B16 -> 0 | AT16: =AO16*$B16 -> 0 | AU16: =AP16*$B16 -> 0 | AV16: =AQ16*$C16 -> 0
A17: =A16+1 -> 2 | B17: =Metadata!C25 -> 0.9335107 | C17: =Metadata!G25 -> 0.97066175 | H17: =SUM(D17:G17) -> 0 | I17: =D17*$B17 -> 0 | J17: =E17*$B17 -> 0 | K17: =F17*$B17 -> 0 | L17: =G17*$C17 -> 0 | Q17: =SUM(M17:P17) -> 0 | R17: =M17*$B17 -> 0 | S17: =N17*$B17 -> 0 | T17: =O17*$B17 -> 0 | U17: =P17*$C17 -> 0 | Z17: =SUM(V17:Y17) -> 0 | AA17: =V17*$B17 -> 0 | AB17: =W17*$B17 -> 0 | AC17: =X17*$B17 -> 0 | AD17: =Y17*$C17 -> 0 | AI17: =SUM(AE17:AH17) -> 0 | AJ17: =AE17*$B17 -> 0 | AK17: =AF17*$B17 -> 0 | AL17: =AG17*$B17 -> 0 | AM17: =AH17*$C17 -> 0 | AR17: =SUM(AN17:AQ17) -> 0 | AS17: =AN17*$B17 -> 0 | AT17: =AO17*$B17 -> 0 | AU17: =AP17*$B17 -> 0 | AV17: =AQ17*$C17 -> 0
A18: =A17+1 -> 3 | B18: =Metadata!C26 -> 0.90194271 | C18: =Metadata!G26 -> 0.95631699 | H18: =SUM(D18:G18) -> 0 | I18: =D18*$B18 -> 0 | J18: =E18*$B18 -> 0 | K18: =F18*$B18 -> 0 | L18: =G18*$C18 -> 0 | Q18: =SUM(M18:P18) -> 0 | R18: =M18*$B18 -> 0 | S18: =N18*$B18 -> 0 | T18: =O18*$B18 -> 0 | U18: =P18*$C18 -> 0 | Z18: =SUM(V18:Y18) -> 0 | AA18: =V18*$B18 -> 0 | AB18: =W18*$B18 -> 0 | AC18: =X18*$B18 -> 0 | AD18: =Y18*$C18 -> 0 | AI18: =SUM(AE18:AH18) -> 0 | AJ18: =AE18*$B18 -> 0 | AK18: =AF18*$B18 -> 0 | AL18: =AG18*$B18 -> 0 | AM18: =AH18*$C18 -> 0 | AR18: =SUM(AN18:AQ18) -> 0 | AS18: =AN18*$B18 -> 0 | AT18: =AO18*$B18 -> 0 | AU18: =AP18*$B18 -> 0 | AV18: =AQ18*$C18 -> 0
A19: =A18+1 -> 4 | B19: =Metadata!C27 -> 0.87144223 | C19: =Metadata!G27 -> 0.94218423 | H19: =SUM(D19:G19) -> 0 | I19: =D19*$B19 -> 0 | J19: =E19*$B19 -> 0 | K19: =F19*$B19 -> 0 | L19: =G19*$C19 -> 0 | Q19: =SUM(M19:P19) -> 0 | R19: =M19*$B19 -> 0 | S19: =N19*$B19 -> 0 | T19: =O19*$B19 -> 0 | U19: =P19*$C19 -> 0 | Z19: =SUM(V19:Y19) -> 0 | AA19: =V19*$B19 -> 0 | AB19: =W19*$B19 -> 0 | AC19: =X19*$B19 -> 0 | AD19: =Y19*$C19 -> 0 | AI19: =SUM(AE19:AH19) -> 0 | AJ19: =AE19*$B19 -> 0 | AK19: =AF19*$B19 -> 0 | AL19: =AG19*$B19 -> 0 | AM19: =AH19*$C19 -> 0 | AR19: =SUM(AN19:AQ19) -> 0 | AS19: =AN19*$B19 -> 0 | AT19: =AO19*$B19 -> 0 | AU19: =AP19*$B19 -> 0 | AV19: =AQ19*$C19 -> 0
A20: =A19+1 -> 5 | B20: =Metadata!C28 -> 0.84197317 | C20: =Metadata!G28 -> 0.92826033 | H20: =SUM(D20:G20) -> 0 | I20: =D20*$B20 -> 0 | J20: =E20*$B20 -> 0 | K20: =F20*$B20 -> 0 | L20: =G20*$C20 -> 0 | Q20: =SUM(M20:P20) -> 0 | R20: =M20*$B20 -> 0 | S20: =N20*$B20 -> 0 | T20: =O20*$B20 -> 0 | U20: =P20*$C20 -> 0 | Z20: =SUM(V20:Y20) -> 0 | AA20: =V20*$B20 -> 0 | AB20: =W20*$B20 -> 0 | AC20: =X20*$B20 -> 0 | AD20: =Y20*$C20 -> 0 | AI20: =SUM(AE20:AH20) -> 0 | AJ20: =AE20*$B20 -> 0 | AK20: =AF20*$B20 -> 0 | AL20: =AG20*$B20 -> 0 | AM20: =AH20*$C20 -> 0 | AR20: =SUM(AN20:AQ20) -> 0 | AS20: =AN20*$B20 -> 0 | AT20: =AO20*$B20 -> 0 | AU20: =AP20*$B20 -> 0 | AV20: =AQ20*$C20 -> 0
A21: =A20+1 -> 6 | B21: =Metadata!C29 -> 0.81350064 | C21: =Metadata!G29 -> 0.91454219 | H21: =SUM(D21:G21) -> 0 | I21: =D21*$B21 -> 0 | J21: =E21*$B21 -> 0 | K21: =F21*$B21 -> 0 | L21: =G21*$C21 -> 0 | Q21: =SUM(M21:P21) -> 0 | R21: =M21*$B21 -> 0 | S21: =N21*$B21 -> 0 | T21: =O21*$B21 -> 0 | U21: =P21*$C21 -> 0 | Z21: =SUM(V21:Y21) -> 0 | AA21: =V21*$B21 -> 0 | AB21: =W21*$B21 -> 0 | AC21: =X21*$B21 -> 0 | AD21: =Y21*$C21 -> 0 | AI21: =SUM(AE21:AH21) -> 0 | AJ21: =AE21*$B21 -> 0 | AK21: =AF21*$B21 -> 0 | AL21: =AG21*$B21 -> 0 | AM21: =AH21*$C21 -> 0 | AR21: =SUM(AN21:AQ21) -> 0 | AS21: =AN21*$B21 -> 0 | AT21: =AO21*$B21 -> 0 | AU21: =AP21*$B21 -> 0 | AV21: =AQ21*$C21 -> 0
A22: =A21+1 -> 7 | B22: =Metadata!C30 -> 0.78599096 | C22: =Metadata!G30 -> 0.90102679 | H22: =SUM(D22:G22) -> 0 | I22: =D22*$B22 -> 0 | J22: =E22*$B22 -> 0 | K22: =F22*$B22 -> 0 | L22: =G22*$C22 -> 0 | Q22: =SUM(M22:P22) -> 0 | R22: =M22*$B22 -> 0 | S22: =N22*$B22 -> 0 | T22: =O22*$B22 -> 0 | U22: =P22*$C22 -> 0 | Z22: =SUM(V22:Y22) -> 0 | AA22: =V22*$B22 -> 0 | AB22: =W22*$B22 -> 0 | AC22: =X22*$B22 -> 0 | AD22: =Y22*$C22 -> 0 | AI22: =SUM(AE22:AH22) -> 0 | AJ22: =AE22*$B22 -> 0 | AK22: =AF22*$B22 -> 0 | AL22: =AG22*$B22 -> 0 | AM22: =AH22*$C22 -> 0 | AR22: =SUM(AN22:AQ22) -> 0 | AS22: =AN22*$B22 -> 0 | AT22: =AO22*$B22 -> 0 | AU22: =AP22*$B22 -> 0 | AV22: =AQ22*$C22 -> 0
A23: =A22+1 -> 8 | B23: =Metadata!C31 -> 0.75941156 | C23: =Metadata!G31 -> 0.88771112 | H23: =SUM(D23:G23) -> 0 | I23: =D23*$B23 -> 0 | J23: =E23*$B23 -> 0 | K23: =F23*$B23 -> 0 | L23: =G23*$C23 -> 0 | Q23: =SUM(M23:P23) -> 0 | R23: =M23*$B23 -> 0 | S23: =N23*$B23 -> 0 | T23: =O23*$B23 -> 0 | U23: =P23*$C23 -> 0 | Z23: =SUM(V23:Y23) -> 0 | AA23: =V23*$B23 -> 0 | AB23: =W23*$B23 -> 0 | AC23: =X23*$B23 -> 0 | AD23: =Y23*$C23 -> 0 | AI23: =SUM(AE23:AH23) -> 0 | AJ23: =AE23*$B23 -> 0 | AK23: =AF23*$B23 -> 0 | AL23: =AG23*$B23 -> 0 | AM23: =AH23*$C23 -> 0 | AR23: =SUM(AN23:AQ23) -> 0 | AS23: =AN23*$B23 -> 0 | AT23: =AO23*$B23 -> 0 | AU23: =AP23*$B23 -> 0 | AV23: =AQ23*$C23 -> 0
A24: =A23+1 -> 9 | B24: =Metadata!C32 -> 0.73373097 | C24: =Metadata!G32 -> 0.87459224 | H24: =SUM(D24:G24) -> 0 | I24: =D24*$B24 -> 0 | J24: =E24*$B24 -> 0 | K24: =F24*$B24 -> 0 | L24: =G24*$C24 -> 0 | Q24: =SUM(M24:P24) -> 0 | R24: =M24*$B24 -> 0 | S24: =N24*$B24 -> 0 | T24: =O24*$B24 -> 0 | U24: =P24*$C24 -> 0 | Z24: =SUM(V24:Y24) -> 0 | AA24: =V24*$B24 -> 0 | AB24: =W24*$B24 -> 0 | AC24: =X24*$B24 -> 0 | AD24: =Y24*$C24 -> 0 | AI24: =SUM(AE24:AH24) -> 0 | AJ24: =AE24*$B24 -> 0 | AK24: =AF24*$B24 -> 0 | AL24: =AG24*$B24 -> 0 | AM24: =AH24*$C24 -> 0 | AR24: =SUM(AN24:AQ24) -> 0 | AS24: =AN24*$B24 -> 0 | AT24: =AO24*$B24 -> 0 | AU24: =AP24*$B24 -> 0 | AV24: =AQ24*$C24 -> 0
A25: =A24+1 -> 10 | B25: =Metadata!C33 -> 0.70891881 | C25: =Metadata!G33 -> 0.86166723 | H25: =SUM(D25:G25) -> 0 | I25: =D25*$B25 -> 0 | J25: =E25*$B25 -> 0 | K25: =F25*$B25 -> 0 | L25: =G25*$C25 -> 0 | Q25: =SUM(M25:P25) -> 0 | R25: =M25*$B25 -> 0 | S25: =N25*$B25 -> 0 | T25: =O25*$B25 -> 0 | U25: =P25*$C25 -> 0 | Z25: =SUM(V25:Y25) -> 0 | AA25: =V25*$B25 -> 0 | AB25: =W25*$B25 -> 0 | AC25: =X25*$B25 -> 0 | AD25: =Y25*$C25 -> 0 | AI25: =SUM(AE25:AH25) -> 0 | AJ25: =AE25*$B25 -> 0 | AK25: =AF25*$B25 -> 0 | AL25: =AG25*$B25 -> 0 | AM25: =AH25*$C25 -> 0 | AR25: =SUM(AN25:AQ25) -> 0 | AS25: =AN25*$B25 -> 0 | AT25: =AO25*$B25 -> 0 | AU25: =AP25*$B25 -> 0 | AV25: =AQ25*$C25 -> 0
A26: =A25+1 -> 11 | B26: =Metadata!C34 -> 0.68494571 | C26: =Metadata!G34 -> 0.84893323 | H26: =SUM(D26:G26) -> 0 | I26: =D26*$B26 -> 0 | J26: =E26*$B26 -> 0 | K26: =F26*$B26 -> 0 | L26: =G26*$C26 -> 0 | Q26: =SUM(M26:P26) -> 0 | R26: =M26*$B26 -> 0 | S26: =N26*$B26 -> 0 | T26: =O26*$B26 -> 0 | U26: =P26*$C26 -> 0 | Z26: =SUM(V26:Y26) -> 0 | AA26: =V26*$B26 -> 0 | AB26: =W26*$B26 -> 0 | AC26: =X26*$B26 -> 0 | AD26: =Y26*$C26 -> 0 | AI26: =SUM(AE26:AH26) -> 0 | AJ26: =AE26*$B26 -> 0 | AK26: =AF26*$B26 -> 0 | AL26: =AG26*$B26 -> 0 | AM26: =AH26*$C26 -> 0 | AR26: =SUM(AN26:AQ26) -> 0 | AS26: =AN26*$B26 -> 0 | AT26: =AO26*$B26 -> 0 | AU26: =AP26*$B26 -> 0 | AV26: =AQ26*$C26 -> 0
A27: =A26+1 -> 12 | B27: =Metadata!C35 -> 0.6617833 | C27: =Metadata!G35 -> 0.83638742 | H27: =SUM(D27:G27) -> 0 | I27: =D27*$B27 -> 0 | J27: =E27*$B27 -> 0 | K27: =F27*$B27 -> 0 | L27: =G27*$C27 -> 0 | Q27: =SUM(M27:P27) -> 0 | R27: =M27*$B27 -> 0 | S27: =N27*$B27 -> 0 | T27: =O27*$B27 -> 0 | U27: =P27*$C27 -> 0 | Z27: =SUM(V27:Y27) -> 0 | AA27: =V27*$B27 -> 0 | AB27: =W27*$B27 -> 0 | AC27: =X27*$B27 -> 0 | AD27: =Y27*$C27 -> 0 | AI27: =SUM(AE27:AH27) -> 0 | AJ27: =AE27*$B27 -> 0 | AK27: =AF27*$B27 -> 0 | AL27: =AG27*$B27 -> 0 | AM27: =AH27*$C27 -> 0 | AR27: =SUM(AN27:AQ27) -> 0 | AS27: =AN27*$B27 -> 0 | AT27: =AO27*$B27 -> 0 | AU27: =AP27*$B27 -> 0 | AV27: =AQ27*$C27 -> 0
... A114: =A113+1 -> 99 | B114: =Metadata!C122 -> 0.052088473 | C114: =Metadata!G122 -> 0.27877724 | H114: =SUM(D114:G114) -> 0 | I114: =D114*$B114 -> 0 | J114: =E114*$B114 -> 0 | K114: =F114*$B114 -> 0 | L114: =G114*$C114 -> 0 | Q114: =SUM(M114:P114) -> 0 | R114: =M114*$B114 -> 0 | S114: =N114*$B114 -> 0 | T114: =O114*$B114 -> 0 | U114: =P114*$C114 -> 0 | Z114: =SUM(V114:Y114) -> 0 | AA114: =V114*$B114 -> 0 | AB114: =W114*$B114 -> 0 | AC114: =X114*$B114 -> 0 | AD114: =Y114*$C114 -> 0 | AI114: =SUM(AE114:AH114) -> 0 | AJ114: =AE114*$B114 -> 0 | AK114: =AF114*$B114 -> 0 | AL114: =AG114*$B114 -> 0 | AM114: =AH114*$C114 -> 0 | AR114: =SUM(AN114:AQ114) -> 0 | AS114: =AN114*$B114 -> 0 | AT114: =AO114*$B114 -> 0 | AU114: =AP114*$B114 -> 0 | AV114: =AQ114*$C114 -> 0

Sheet Metadata
F1: Metadata | I1: Sheet Nr.
A2: Discount Rates
I6: Source: Green Book, HM Treasury 2020
I7: Ref: Table 6 - Declining Long Term Discoun Rate
I8: https://www.gov.uk/government/publications/the-green-book-appraisal-and-evaluation-in-central-governent/the-green-book-2020#valuation-of-costs-and-benefits
B21: Standard | F21: Health
A22: Year | B22: Annual rate | C22: Discount factor | D22: Cumulative | F22: Annual rate | G22: Discount factor | H22: Cumulative
A23: 0 | B23: 0.035 | C23: =1/(1+B23)^A23 -> 1 | D23: =C23 -> 1 | F23: 0.015 | G23: =1/(1+F23)^E23 -> 1 | H23: =G23 -> 1
A24: 1 | B24: 0.035 | C24: =C23/(1+B24) -> 0.96618357 | D24: =D23+C24 -> 1.9661836 | F24: 0.015 | G24: =G23/(1+F24) -> 0.98522167 | H24: =H23+G24 -> 1.9852217
A25: 2 | B25: 0.035 | C25: =C24/(1+B25) -> 0.9335107 | D25: =D24+C25 -> 2.8996943 | F25: 0.015 | G25: =G24/(1+F25) -> 0.97066175 | H25: =H24+G25 -> 2.9558834
A26: 3 | B26: 0.035 | C26: =C25/(1+B26) -> 0.90194271 | D26: =D25+C26 -> 3.801637 | F26: 0.015 | G26: =G25/(1+F26) -> 0.95631699 | H26: =H25+G26 -> 3.9122004
A27: 4 | B27: 0.035 | C27: =C26/(1+B27) -> 0.87144223 | D27: =D26+C27 -> 4.6730792 | F27: 0.015 | G27: =G26/(1+F27) -> 0.94218423 | H27: =H26+G27 -> 4.8543846
A28: 5 | B28: 0.035 | C28: =C27/(1+B28) -> 0.84197317 | D28: =D27+C28 -> 5.5150524 | F28: 0.015 | G28: =G27/(1+F28) -> 0.92826033 | H28: =H27+G28 -> 5.782645
A29: 6 | B29: 0.035 | C29: =C28/(1+B29) -> 0.81350064 | D29: =D28+C29 -> 6.328553 | F29: 0.015 | G29: =G28/(1+F29) -> 0.91454219 | H29: =H28+G29 -> 6.6971872
A30: 7 | B30: 0.035 | C30: =C29/(1+B30) -> 0.78599096 | D30: =D29+C30 -> 7.114544 | F30: 0.015 | G30: =G29/(1+F30) -> 0.90102679 | H30: =H29+G30 -> 7.598214
A31: 8 | B31: 0.035 | C31: =C30/(1+B31) -> 0.75941156 | D31: =D30+C31 -> 7.8739555 | F31: 0.015 | G31: =G30/(1+F31) -> 0.88771112 | H31: =H30+G31 -> 8.4859251
A32: 9 | B32: 0.035 | C32: =C31/(1+B32) -> 0.73373097 | D32: =D31+C32 -> 8.6076865 | F32: 0.015 | G32: =G31/(1+F32) -> 0.87459224 | H32: =H31+G32 -> 9.3605173
A33: 10 | B33: 0.035 | C33: =C32/(1+B33) -> 0.70891881 | D33: =D32+C33 -> 9.3166053 | F33: 0.015 | G33: =G32/(1+F33) -> 0.86166723 | H33: =H32+G33 -> 10.222185
A34: 11 | B34: 0.035 | C34: =C33/(1+B34) -> 0.68494571 | D34: =D33+C34 -> 10.001551 | F34: 0.015 | G34: =G33/(1+F34) -> 0.84893323 | H34: =H33+G34 -> 11.071118
A35: 12 | B35: 0.035 | C35: =C34/(1+B35) -> 0.6617833 | D35: =D34+C35 -> 10.663334 | F35: 0.015 | G35: =G34/(1+F35) -> 0.83638742 | H35: =H34+G35 -> 11.907505
... A223: 200 | B223: 0.025 | C223: =C222/(1+B223) -> 0.0043016119 | D223: =D222+C223 -> 31.72402 | F223: 0.01071 | G223: =G222/(1+F223) -> 0.095054896 | H223: =H222+G223 -> 71.508309
